Workbook

Sheet Tổng hợp thu hồi
A1: Đối tác/Đơn phát sinh | B1: Phân loại | C1: Tháng phát sinh | D1: SKU | E1: Tên SP | F1: Brand | G1: SL thực nhận | H1: SL đã xuất | I1: Còn lại | J1: Tình trạng sản phẩm | K1: Hạn sử dụng sản phẩm | L1: Ngày làm chuẩn | M1: HSD tiêu chuẩn (tháng) | N1: HSD còn lại (tháng) | O1: % hạn sản phẩm còn lại | P1: Mã tham chiếu | Q1: Ghi chú | R1: Ngày cập nhập
A2: Guardian | B2: B2B | C2: Tháng 8 | D2: 8809491946260 | E2: Son môi GLAMRR Q (LONG WEAR LIP CREAM #12 LAVISH, 5g) | F2: =IF(ISNUMBER(SEARCH("gilaa",E2)),"GILAA", IF(ISNUMBER(SEARCH("GLAMRR Q",E2)),"GLAMRR Q", IF(ISNUMBER(SEARCH("BAD PEACH",E2)),"BAD PEACH", IF(ISNUMBER(SEARCH("VEGICK",E2)),"VEGICK", IF(ISNUMBER(SEARCH("DE MEMORIA",E2)),"DE MEMORIA", IF(ISNUMBER(SEARCH("MUDE",E2)),"MUDE", IF(ISNUMBER(SEARCH("daoida",E2)),"DAOIDA",IF(ISNUMBER(SEARCH("MEDIFORCELL",E2)),"MEDIFORCELL",IF(ISNUMBER(SEARCH("PLU",E2)),"PLU",""))))))))) -> GLAMRR Q | G2: 1 | I2: =G2-H2 -> 1 | J2: bao bì không có in date/lot | K2: - | L2: - | M2: - | N2: - | O2: - | R2: 20/3/2026
A3: Guardian | B3: B2B | C3: Tháng 8 | D3: 8809783326817 | E3: Son môi GLAMRR Q (V​E​G​A​N S​U​P​E​R L​I​P B​A​L​M 0​4 O​'​P​E​A​C​H, 4.5g) | F3: =IF(ISNUMBER(SEARCH("gilaa",E3)),"GILAA", IF(ISNUMBER(SEARCH("GLAMRR Q",E3)),"GLAMRR Q", IF(ISNUMBER(SEARCH("BAD PEACH",E3)),"BAD PEACH", IF(ISNUMBER(SEARCH("VEGICK",E3)),"VEGICK", IF(ISNUMBER(SEARCH("DE MEMORIA",E3)),"DE MEMORIA", IF(ISNUMBER(SEARCH("MUDE",E3)),"MUDE", IF(ISNUMBER(SEARCH("daoida",E3)),"DAOIDA",IF(ISNUMBER(SEARCH("MEDIFORCELL",E3)),"MEDIFORCELL",IF(ISNUMBER(SEARCH("PLU",E3)),"PLU",""))))))))) -> GLAMRR Q | G3: 2 | I3: =G3-H3 -> 2 | J3: bao bì bị bạc màu | K3: 45968 | L3: =TODAY() -> 46106 | M3: 36 | N3: =(K3-L3)/30 -> -4.6 | O3: =N3/M3 -> -0.12777778 | R3: 20/3/2026
A4: Guardian | B4: B2B | C4: Tháng 8 | D4: 8809491946154 | E4: Son môi GLAMRR Q (LONG WEAR LIP CREAM #01 GLAD DAY, 5g) | F4: =IF(ISNUMBER(SEARCH("gilaa",E4)),"GILAA", IF(ISNUMBER(SEARCH("GLAMRR Q",E4)),"GLAMRR Q", IF(ISNUMBER(SEARCH("BAD PEACH",E4)),"BAD PEACH", IF(ISNUMBER(SEARCH("VEGICK",E4)),"VEGICK", IF(ISNUMBER(SEARCH("DE MEMORIA",E4)),"DE MEMORIA", IF(ISNUMBER(SEARCH("MUDE",E4)),"MUDE", IF(ISNUMBER(SEARCH("daoida",E4)),"DAOIDA",IF(ISNUMBER(SEARCH("MEDIFORCELL",E4)),"MEDIFORCELL",IF(ISNUMBER(SEARCH("PLU",E4)),"PLU",""))))))))) -> GLAMRR Q | G4: 15 | I4: =G4-H4 -> 15 | J4: bao bì bị bạc màu | K4: 46052 | L4: =TODAY() -> 46106 | M4: 36 | N4: =(K4-L4)/30 -> -1.8 | O4: =N4/M4 -> -0.05 | R4: 20/3/2026
A5: Guardian | B5: B2B | C5: Tháng 8 | D5: 8809875904862 | E5: Phấn nước trang điểm GLAMRR Q (VEGAN SUPER COVER CUSHION #01 LIGHT BEIGE, 15g) | F5: =IF(ISNUMBER(SEARCH("gilaa",E5)),"GILAA", IF(ISNUMBER(SEARCH("GLAMRR Q",E5)),"GLAMRR Q", IF(ISNUMBER(SEARCH("BAD PEACH",E5)),"BAD PEACH", IF(ISNUMBER(SEARCH("VEGICK",E5)),"VEGICK", IF(ISNUMBER(SEARCH("DE MEMORIA",E5)),"DE MEMORIA", IF(ISNUMBER(SEARCH("MUDE",E5)),"MUDE", IF(ISNUMBER(SEARCH("daoida",E5)),"DAOIDA",IF(ISNUMBER(SEARCH("MEDIFORCELL",E5)),"MEDIFORCELL",IF(ISNUMBER(SEARCH("PLU",E5)),"PLU",""))))))))) -> GLAMRR Q | G5: 1 | I5: =G5-H5 -> 1 | J5: bao bì bị bạc màu | K5: 46052 | L5: =TODAY() -> 46106 | M5: 36 | N5: =(K5-L5)/30 -> -1.8 | O5: =N5/M5 -> -0.05 | R5: 20/3/2026
A6: Guardian | B6: B2B | C6: Tháng 8 | D6: 8809526841393 | E6: Phấn nước trang điểm GLAMRR Q (VEGAN SUPER GLOW CUSHION #01 LIGHT BEIGE, 15g) | F6: =IF(ISNUMBER(SEARCH("gilaa",E6)),"GILAA", IF(ISNUMBER(SEARCH("GLAMRR Q",E6)),"GLAMRR Q", IF(ISNUMBER(SEARCH("BAD PEACH",E6)),"BAD PEACH", IF(ISNUMBER(SEARCH("VEGICK",E6)),"VEGICK", IF(ISNUMBER(SEARCH("DE MEMORIA",E6)),"DE MEMORIA", IF(ISNUMBER(SEARCH("MUDE",E6)),"MUDE", IF(ISNUMBER(SEARCH("daoida",E6)),"DAOIDA",IF(ISNUMBER(SEARCH("MEDIFORCELL",E6)),"MEDIFORCELL",IF(ISNUMBER(SEARCH("PLU",E6)),"PLU",""))))))))) -> GLAMRR Q | G6: 5 | I6: =G6-H6 -> 5 | J6: bao bì bị bạc màu | K6: 46055 | L6: =TODAY() -> 46106 | M6: 36 | N6: =(K6-L6)/30 -> -1.7 | O6: =N6/M6 -> -0.047222222 | R6: 20/3/2026
A7: Guardian | B7: B2B | C7: Tháng 8 | D7: 8809526841393 | E7: Phấn nước trang điểm GLAMRR Q (VEGAN SUPER GLOW CUSHION #01 LIGHT BEIGE, 15g) | F7: =IF(ISNUMBER(SEARCH("gilaa",E7)),"GILAA", IF(ISNUMBER(SEARCH("GLAMRR Q",E7)),"GLAMRR Q", IF(ISNUMBER(SEARCH("BAD PEACH",E7)),"BAD PEACH", IF(ISNUMBER(SEARCH("VEGICK",E7)),"VEGICK", IF(ISNUMBER(SEARCH("DE MEMORIA",E7)),"DE MEMORIA", IF(ISNUMBER(SEARCH("MUDE",E7)),"MUDE", IF(ISNUMBER(SEARCH("daoida",E7)),"DAOIDA",IF(ISNUMBER(SEARCH("MEDIFORCELL",E7)),"MEDIFORCELL",IF(ISNUMBER(SEARCH("PLU",E7)),"PLU",""))))))))) -> GLAMRR Q | G7: 1 | I7: =G7-H7 -> 1 | J7: bao bì bị cấn móp | K7: 46055 | L7: =TODAY() -> 46106 | M7: 36 | N7: =(K7-L7)/30 -> -1.7 | O7: =N7/M7 -> -0.047222222 | R7: 20/3/2026
A8: Guardian | B8: B2B | C8: Tháng 8 | D8: 8809526841409 | E8: Phấn nước trang điểm GLAMRR Q (VEGAN SUPER GLOW CUSHION #02 NATURAL BEIGE, 15g) | F8: =IF(ISNUMBER(SEARCH("gilaa",E8)),"GILAA", IF(ISNUMBER(SEARCH("GLAMRR Q",E8)),"GLAMRR Q", IF(ISNUMBER(SEARCH("BAD PEACH",E8)),"BAD PEACH", IF(ISNUMBER(SEARCH("VEGICK",E8)),"VEGICK", IF(ISNUMBER(SEARCH("DE MEMORIA",E8)),"DE MEMORIA", IF(ISNUMBER(SEARCH("MUDE",E8)),"MUDE", IF(ISNUMBER(SEARCH("daoida",E8)),"DAOIDA",IF(ISNUMBER(SEARCH("MEDIFORCELL",E8)),"MEDIFORCELL",IF(ISNUMBER(SEARCH("PLU",E8)),"PLU",""))))))))) -> GLAMRR Q | G8: 1 | I8: =G8-H8 -> 1 | J8: bao bì bị bạc màu | K8: 46056 | L8: =TODAY() -> 46106 | M8: 36 | N8: =(K8-L8)/30 -> -1.6666667 | O8: =N8/M8 -> -0.046296296 | R8: 20/3/2026
A9: Guardian | B9: B2B | C9: Tháng 8 | D9: 8809526841409 | E9: Phấn nước trang điểm GLAMRR Q (VEGAN SUPER GLOW CUSHION #02 NATURAL BEIGE, 15g) | F9: =IF(ISNUMBER(SEARCH("gilaa",E9)),"GILAA", IF(ISNUMBER(SEARCH("GLAMRR Q",E9)),"GLAMRR Q", IF(ISNUMBER(SEARCH("BAD PEACH",E9)),"BAD PEACH", IF(ISNUMBER(SEARCH("VEGICK",E9)),"VEGICK", IF(ISNUMBER(SEARCH("DE MEMORIA",E9)),"DE MEMORIA", IF(ISNUMBER(SEARCH("MUDE",E9)),"MUDE", IF(ISNUMBER(SEARCH("daoida",E9)),"DAOIDA",IF(ISNUMBER(SEARCH("MEDIFORCELL",E9)),"MEDIFORCELL",IF(ISNUMBER(SEARCH("PLU",E9)),"PLU",""))))))))) -> GLAMRR Q | G9: 1 | I9: =G9-H9 -> 1 | J9: sản phẩm nguyên vẹn | K9: 46056 | L9: =TODAY() -> 46106 | M9: 36 | N9: =(K9-L9)/30 -> -1.6666667 | O9: =N9/M9 -> -0.046296296 | R9: 20/3/2026
A10: Guardian | B10: B2B | C10: Tháng 8 | D10: 8809526841409 | E10: Phấn nước trang điểm GLAMRR Q (VEGAN SUPER GLOW CUSHION #02 NATURAL BEIGE, 15g) | F10: =IF(ISNUMBER(SEARCH("gilaa",E10)),"GILAA", IF(ISNUMBER(SEARCH("GLAMRR Q",E10)),"GLAMRR Q", IF(ISNUMBER(SEARCH("BAD PEACH",E10)),"BAD PEACH", IF(ISNUMBER(SEARCH("VEGICK",E10)),"VEGICK", IF(ISNUMBER(SEARCH("DE MEMORIA",E10)),"DE MEMORIA", IF(ISNUMBER(SEARCH("MUDE",E10)),"MUDE", IF(ISNUMBER(SEARCH("daoida",E10)),"DAOIDA",IF(ISNUMBER(SEARCH("MEDIFORCELL",E10)),"MEDIFORCELL",IF(ISNUMBER(SEARCH("PLU",E10)),"PLU",""))))))))) -> GLAMRR Q | G10: 2 | I10: =G10-H10 -> 2 | J10: bao bì bị cấn móp | K10: 46056 | L10: =TODAY() -> 46106 | M10: 36 | N10: =(K10-L10)/30 -> -1.6666667 | O10: =N10/M10 -> -0.046296296 | R10: 20/3/2026
A11: Guardian | B11: B2B | C11: Tháng 8 | D11: 8809526841409 | E11: Phấn nước trang điểm GLAMRR Q (VEGAN SUPER GLOW CUSHION #02 NATURAL BEIGE, 15g) | F11: =IF(ISNUMBER(SEARCH("gilaa",E11)),"GILAA", IF(ISNUMBER(SEARCH("GLAMRR Q",E11)),"GLAMRR Q", IF(ISNUMBER(SEARCH("BAD PEACH",E11)),"BAD PEACH", IF(ISNUMBER(SEARCH("VEGICK",E11)),"VEGICK", IF(ISNUMBER(SEARCH("DE MEMORIA",E11)),"DE MEMORIA", IF(ISNUMBER(SEARCH("MUDE",E11)),"MUDE", IF(ISNUMBER(SEARCH("daoida",E11)),"DAOIDA",IF(ISNUMBER(SEARCH("MEDIFORCELL",E11)),"MEDIFORCELL",IF(ISNUMBER(SEARCH("PLU",E11)),"PLU",""))))))))) -> GLAMRR Q | G11: 14 | I11: =G11-H11 -> 14 | J11: bao bì bị bạc màu | K11: 46056 | L11: =TODAY() -> 46106 | M11: 36 | N11: =(K11-L11)/30 -> -1.6666667 | O11: =N11/M11 -> -0.046296296 | R11: 20/3/2026
A12: Guardian | B12: B2B | C12: Tháng 8 | D12: 8809563069910 | E12: Mặt nạ ngủ môi GLAMRR Q (VEGAN B5 SUPER LIP SLEEPING MASK, 10ml) | F12: =IF(ISNUMBER(SEARCH("gilaa",E12)),"GILAA", IF(ISNUMBER(SEARCH("GLAMRR Q",E12)),"GLAMRR Q", IF(ISNUMBER(SEARCH("BAD PEACH",E12)),"BAD PEACH", IF(ISNUMBER(SEARCH("VEGICK",E12)),"VEGICK", IF(ISNUMBER(SEARCH("DE MEMORIA",E12)),"DE MEMORIA", IF(ISNUMBER(SEARCH("MUDE",E12)),"MUDE", IF(ISNUMBER(SEARCH("daoida",E12)),"DAOIDA",IF(ISNUMBER(SEARCH("MEDIFORCELL",E12)),"MEDIFORCELL",IF(ISNUMBER(SEARCH("PLU",E12)),"PLU",""))))))))) -> GLAMRR Q | G12: 1 | I12: =G12-H12 -> 1 | J12: bao bì bị bạc màu | K12: 46056 | L12: =TODAY() -> 46106 | M12: 36 | N12: =(K12-L12)/30 -> -1.6666667 | O12: =N12/M12 -> -0.046296296 | R12: 20/3/2026
A13: Guardian | B13: B2B | C13: Tháng 8 | D13: 8809491946161 | E13: Son môi GLAMRR Q (LONG WEAR LIP CREAM #02 LOVELY DAY, 5g) | F13: =IF(ISNUMBER(SEARCH("gilaa",E13)),"GILAA", IF(ISNUMBER(SEARCH("GLAMRR Q",E13)),"GLAMRR Q", IF(ISNUMBER(SEARCH("BAD PEACH",E13)),"BAD PEACH", IF(ISNUMBER(SEARCH("VEGICK",E13)),"VEGICK", IF(ISNUMBER(SEARCH("DE MEMORIA",E13)),"DE MEMORIA", IF(ISNUMBER(SEARCH("MUDE",E13)),"MUDE", IF(ISNUMBER(SEARCH("daoida",E13)),"DAOIDA",IF(ISNUMBER(SEARCH("MEDIFORCELL",E13)),"MEDIFORCELL",IF(ISNUMBER(SEARCH("PLU",E13)),"PLU",""))))))))) -> GLAMRR Q | G13: 1 | I13: =G13-H13 -> 1 | J13: sản phẩm nguyên vẹn | K13: 46061 | L13: =TODAY() -> 46106 | M13: 36 | N13: =(K13-L13)/30 -> -1.5 | O13: =N13/M13 -> -0.041666667 | R13: 20/3/2026
A14: Guardian | B14: B2B | C14: Tháng 8 | D14: 8809491946161 | E14: Son môi GLAMRR Q (LONG WEAR LIP CREAM #02 LOVELY DAY, 5g) | F14: =IF(ISNUMBER(SEARCH("gilaa",E14)),"GILAA", IF(ISNUMBER(SEARCH("GLAMRR Q",E14)),"GLAMRR Q", IF(ISNUMBER(SEARCH("BAD PEACH",E14)),"BAD PEACH", IF(ISNUMBER(SEARCH("VEGICK",E14)),"VEGICK", IF(ISNUMBER(SEARCH("DE MEMORIA",E14)),"DE MEMORIA", IF(ISNUMBER(SEARCH("MUDE",E14)),"MUDE", IF(ISNUMBER(SEARCH("daoida",E14)),"DAOIDA",IF(ISNUMBER(SEARCH("MEDIFORCELL",E14)),"MEDIFORCELL",IF(ISNUMBER(SEARCH("PLU",E14)),"PLU",""))))))))) -> GLAMRR Q | G14: 45 | I14: =G14-H14 -> 45 | J14: bao bì bị bạc màu | K14: 46061 | L14: =TODAY() -> 46106 | M14: 36 | N14: =(K14-L14)/30 -> -1.5 | O14: =N14/M14 -> -0.041666667 | R14: 20/3/2026
... A41: Guardian | B41: B2B | C41: Tháng 8 | D41: 8809563069910 | E41: Mặt nạ ngủ môi GLAMRR Q (VEGAN B5 SUPER LIP SLEEPING MASK, 10ml) | F41: =IF(ISNUMBER(SEARCH("gilaa",E41)),"GILAA", IF(ISNUMBER(SEARCH("GLAMRR Q",E41)),"GLAMRR Q", IF(ISNUMBER(SEARCH("BAD PEACH",E41)),"BAD PEACH", IF(ISNUMBER(SEARCH("VEGICK",E41)),"VEGICK", IF(ISNUMBER(SEARCH("DE MEMORIA",E41)),"DE MEMORIA", IF(ISNUMBER(SEARCH("MUDE",E41)),"MUDE", IF(ISNUMBER(SEARCH("daoida",E41)),"DAOIDA",IF(ISNUMBER(SEARCH("MEDIFORCELL",E41)),"MEDIFORCELL",IF(ISNUMBER(SEARCH("PLU",E41)),"PLU",""))))))))) -> GLAMRR Q | G41: 3 | I41: =G41-H41 -> 3 | J41: sản phẩm nguyên vẹn | K41: 46068 | L41: =TODAY() -> 46106 | M41: 36 | N41: =(K41-L41)/30 -> -1.2666667 | O41: =N41/M41 -> -0.035185185 | R41: 20/3/2026
A42: Guardian | B42: B2B | C42: Tháng 8 | D42: 8809203078227 | E42: Thực phẩm bổ sung GILAA (5K COLLAGEN INNER BOOSTER WITH PEONY, 20g x 15), hộp 15 gói | F42: =IF(ISNUMBER(SEARCH("gilaa",E42)),"GILAA", IF(ISNUMBER(SEARCH("GLAMRR Q",E42)),"GLAMRR Q", IF(ISNUMBER(SEARCH("BAD PEACH",E42)),"BAD PEACH", IF(ISNUMBER(SEARCH("VEGICK",E42)),"VEGICK", IF(ISNUMBER(SEARCH("DE MEMORIA",E42)),"DE MEMORIA", IF(ISNUMBER(SEARCH("MUDE",E42)),"MUDE", IF(ISNUMBER(SEARCH("daoida",E42)),"DAOIDA",IF(ISNUMBER(SEARCH("MEDIFORCELL",E42)),"MEDIFORCELL",IF(ISNUMBER(SEARCH("PLU",E42)),"PLU",""))))))))) -> GILAA | G42: 4 | I42: =G42-H42 -> 4 | J42: bao bì bị bạc màu | K42: 46074 | L42: =TODAY() -> 46106 | M42: 36 | N42: =(K42-L42)/30 -> -1.0666667 | O42: =N42/M42 -> -0.02962963 | Q42: B2B lên đơn trên CRM, KT check sl giúp nha | R42: 20/3/2026
A43: Guardian | B43: B2B | C43: Tháng 8 | D43: 8809491946260 | E43: Son môi GLAMRR Q (LONG WEAR LIP CREAM #12 LAVISH, 5g) | F43: =IF(ISNUMBER(SEARCH("gilaa",E43)),"GILAA", IF(ISNUMBER(SEARCH("GLAMRR Q",E43)),"GLAMRR Q", IF(ISNUMBER(SEARCH("BAD PEACH",E43)),"BAD PEACH", IF(ISNUMBER(SEARCH("VEGICK",E43)),"VEGICK", IF(ISNUMBER(SEARCH("DE MEMORIA",E43)),"DE MEMORIA", IF(ISNUMBER(SEARCH("MUDE",E43)),"MUDE", IF(ISNUMBER(SEARCH("daoida",E43)),"DAOIDA",IF(ISNUMBER(SEARCH("MEDIFORCELL",E43)),"MEDIFORCELL",IF(ISNUMBER(SEARCH("PLU",E43)),"PLU",""))))))))) -> GLAMRR Q | G43: 3 | I43: =G43-H43 -> 3 | J43: bao bì bị bạc màu | K43: 46082 | L43: =TODAY() -> 46106 | M43: 36 | N43: =(K43-L43)/30 -> -0.8 | O43: =N43/M43 -> -0.022222222 | R43: 20/3/2026
A44: Guardian | B44: B2B | C44: Tháng 8 | D44: 8809491946260 | E44: Son môi GLAMRR Q (LONG WEAR LIP CREAM #12 LAVISH, 5g) | F44: =IF(ISNUMBER(SEARCH("gilaa",E44)),"GILAA", IF(ISNUMBER(SEARCH("GLAMRR Q",E44)),"GLAMRR Q", IF(ISNUMBER(SEARCH("BAD PEACH",E44)),"BAD PEACH", IF(ISNUMBER(SEARCH("VEGICK",E44)),"VEGICK", IF(ISNUMBER(SEARCH("DE MEMORIA",E44)),"DE MEMORIA", IF(ISNUMBER(SEARCH("MUDE",E44)),"MUDE", IF(ISNUMBER(SEARCH("daoida",E44)),"DAOIDA",IF(ISNUMBER(SEARCH("MEDIFORCELL",E44)),"MEDIFORCELL",IF(ISNUMBER(SEARCH("PLU",E44)),"PLU",""))))))))) -> GLAMRR Q | G44: 10 | I44: =G44-H44 -> 10 | J44: sản phẩm nguyên vẹn | K44: 46082 | L44: =TODAY() -> 46106 | M44: 36 | N44: =(K44-L44)/30 -> -0.8 | O44: =N44/M44 -> -0.022222222 | R44: 20/3/2026
A45: Guardian | B45: B2B | C45: Tháng 8 | D45: 8809875904862 | E45: Phấn nước trang điểm GLAMRR Q (VEGAN SUPER COVER CUSHION #01 LIGHT BEIGE, 15g) | F45: =IF(ISNUMBER(SEARCH("gilaa",E45)),"GILAA", IF(ISNUMBER(SEARCH("GLAMRR Q",E45)),"GLAMRR Q", IF(ISNUMBER(SEARCH("BAD PEACH",E45)),"BAD PEACH", IF(ISNUMBER(SEARCH("VEGICK",E45)),"VEGICK", IF(ISNUMBER(SEARCH("DE MEMORIA",E45)),"DE MEMORIA", IF(ISNUMBER(SEARCH("MUDE",E45)),"MUDE", IF(ISNUMBER(SEARCH("daoida",E45)),"DAOIDA",IF(ISNUMBER(SEARCH("MEDIFORCELL",E45)),"MEDIFORCELL",IF(ISNUMBER(SEARCH("PLU",E45)),"PLU",""))))))))) -> GLAMRR Q | G45: 15 | I45: =G45-H45 -> 15 | J45: sản phẩm nguyên vẹn | K45: 46089 | L45: =TODAY() -> 46106 | M45: 36 | N45: =(K45-L45)/30 -> -0.56666667 | O45: =N45/M45 -> -0.015740741 | R45: 20/3/2026
A46: Guardian | B46: B2B | C46: Tháng 8 | D46: 8809875904862 | E46: Phấn nước trang điểm GLAMRR Q (VEGAN SUPER COVER CUSHION #01 LIGHT BEIGE, 15g) | F46: =IF(ISNUMBER(SEARCH("gilaa",E46)),"GILAA", IF(ISNUMBER(SEARCH("GLAMRR Q",E46)),"GLAMRR Q", IF(ISNUMBER(SEARCH("BAD PEACH",E46)),"BAD PEACH", IF(ISNUMBER(SEARCH("VEGICK",E46)),"VEGICK", IF(ISNUMBER(SEARCH("DE MEMORIA",E46)),"DE MEMORIA", IF(ISNUMBER(SEARCH("MUDE",E46)),"MUDE", IF(ISNUMBER(SEARCH("daoida",E46)),"DAOIDA",IF(ISNUMBER(SEARCH("MEDIFORCELL",E46)),"MEDIFORCELL",IF(ISNUMBER(SEARCH("PLU",E46)),"PLU",""))))))))) -> GLAMRR Q | G46: 17 | I46: =G46-H46 -> 17 | J46: bao bì bị bạc màu | K46: 46089 | L46: =TODAY() -> 46106 | M46: 36 | N46: =(K46-L46)/30 -> -0.56666667 | O46: =N46/M46 -> -0.015740741 | R46: 20/3/2026
A47: Guardian | B47: B2B | C47: Tháng 8 | D47: 8809875904879 | E47: Phấn nước trang điểm GLAMRR Q (VEGAN SUPER COVER CUSHION #02 NATURAL BEIGE, 15g) | F47: =IF(ISNUMBER(SEARCH("gilaa",E47)),"GILAA", IF(ISNUMBER(SEARCH("GLAMRR Q",E47)),"GLAMRR Q", IF(ISNUMBER(SEARCH("BAD PEACH",E47)),"BAD PEACH", IF(ISNUMBER(SEARCH("VEGICK",E47)),"VEGICK", IF(ISNUMBER(SEARCH("DE MEMORIA",E47)),"DE MEMORIA", IF(ISNUMBER(SEARCH("MUDE",E47)),"MUDE", IF(ISNUMBER(SEARCH("daoida",E47)),"DAOIDA",IF(ISNUMBER(SEARCH("MEDIFORCELL",E47)),"MEDIFORCELL",IF(ISNUMBER(SEARCH("PLU",E47)),"PLU",""))))))))) -> GLAMRR Q | G47: 13 | I47: =G47-H47 -> 13 | J47: sản phẩm nguyên vẹn | K47: 46090 | L47: =TODAY() -> 46106 | M47: 36 | N47: =(K47-L47)/30 -> -0.53333333 | O47: =N47/M47 -> -0.014814815 | R47: 20/3/2026
A48: Guardian | B48: B2B | C48: Tháng 8 | D48: 8809875904879 | E48: Phấn nước trang điểm GLAMRR Q (VEGAN SUPER COVER CUSHION #02 NATURAL BEIGE, 15g) | F48: =IF(ISNUMBER(SEARCH("gilaa",E48)),"GILAA", IF(ISNUMBER(SEARCH("GLAMRR Q",E48)),"GLAMRR Q", IF(ISNUMBER(SEARCH("BAD PEACH",E48)),"BAD PEACH", IF(ISNUMBER(SEARCH("VEGICK",E48)),"VEGICK", IF(ISNUMBER(SEARCH("DE MEMORIA",E48)),"DE MEMORIA", IF(ISNUMBER(SEARCH("MUDE",E48)),"MUDE", IF(ISNUMBER(SEARCH("daoida",E48)),"DAOIDA",IF(ISNUMBER(SEARCH("MEDIFORCELL",E48)),"MEDIFORCELL",IF(ISNUMBER(SEARCH("PLU",E48)),"PLU",""))))))))) -> GLAMRR Q | G48: 34 | I48: =G48-H48 -> 34 | J48: bao bì bị bạc màu | K48: 46090 | L48: =TODAY() -> 46106 | M48: 36 | N48: =(K48-L48)/30 -> -0.53333333 | O48: =N48/M48 -> -0.014814815 | R48: 20/3/2026
A49: Guardian | B49: B2B | C49: Tháng 8 | D49: 8809526841393 | E49: Phấn nước trang điểm GLAMRR Q (VEGAN SUPER GLOW CUSHION #01 LIGHT BEIGE, 15g) | F49: =IF(ISNUMBER(SEARCH("gilaa",E49)),"GILAA", IF(ISNUMBER(SEARCH("GLAMRR Q",E49)),"GLAMRR Q", IF(ISNUMBER(SEARCH("BAD PEACH",E49)),"BAD PEACH", IF(ISNUMBER(SEARCH("VEGICK",E49)),"VEGICK", IF(ISNUMBER(SEARCH("DE MEMORIA",E49)),"DE MEMORIA", IF(ISNUMBER(SEARCH("MUDE",E49)),"MUDE", IF(ISNUMBER(SEARCH("daoida",E49)),"DAOIDA",IF(ISNUMBER(SEARCH("MEDIFORCELL",E49)),"MEDIFORCELL",IF(ISNUMBER(SEARCH("PLU",E49)),"PLU",""))))))))) -> GLAMRR Q | G49: 12 | I49: =G49-H49 -> 12 | J49: bao bì bị bạc màu | K49: 46104 | L49: =TODAY() -> 46106 | M49: 36 | N49: =(K49-L49)/30 -> -0.066666667 | O49: =N49/M49 -> -0.0018518519 | R49: 20/3/2026
A50: Guardian | B50: B2B | C50: Tháng 8 | D50: 8809526841393 | E50: Phấn nước trang điểm GLAMRR Q (VEGAN SUPER GLOW CUSHION #01 LIGHT BEIGE, 15g) | F50: =IF(ISNUMBER(SEARCH("gilaa",E50)),"GILAA", IF(ISNUMBER(SEARCH("GLAMRR Q",E50)),"GLAMRR Q", IF(ISNUMBER(SEARCH("BAD PEACH",E50)),"BAD PEACH", IF(ISNUMBER(SEARCH("VEGICK",E50)),"VEGICK", IF(ISNUMBER(SEARCH("DE MEMORIA",E50)),"DE MEMORIA", IF(ISNUMBER(SEARCH("MUDE",E50)),"MUDE", IF(ISNUMBER(SEARCH("daoida",E50)),"DAOIDA",IF(ISNUMBER(SEARCH("MEDIFORCELL",E50)),"MEDIFORCELL",IF(ISNUMBER(SEARCH("PLU",E50)),"PLU",""))))))))) -> GLAMRR Q | G50: 1 | I50: =G50-H50 -> 1 | J50: bao bì bị cấn móp | K50: 46104 | L50: =TODAY() -> 46106 | M50: 36 | N50: =(K50-L50)/30 -> -0.066666667 | O50: =N50/M50 -> -0.0018518519 | R50: 20/3/2026
A51: Guardian | B51: B2B | C51: Tháng 8 | D51: 8809526841409 | E51: Phấn nước trang điểm GLAMRR Q (VEGAN SUPER GLOW CUSHION #02 NATURAL BEIGE, 15g) | F51: =IF(ISNUMBER(SEARCH("gilaa",E51)),"GILAA", IF(ISNUMBER(SEARCH("GLAMRR Q",E51)),"GLAMRR Q", IF(ISNUMBER(SEARCH("BAD PEACH",E51)),"BAD PEACH", IF(ISNUMBER(SEARCH("VEGICK",E51)),"VEGICK", IF(ISNUMBER(SEARCH("DE MEMORIA",E51)),"DE MEMORIA", IF(ISNUMBER(SEARCH("MUDE",E51)),"MUDE", IF(ISNUMBER(SEARCH("daoida",E51)),"DAOIDA",IF(ISNUMBER(SEARCH("MEDIFORCELL",E51)),"MEDIFORCELL",IF(ISNUMBER(SEARCH("PLU",E51)),"PLU",""))))))))) -> GLAMRR Q | G51: 10 | I51: =G51-H51 -> 10 | J51: bao bì bị bạc màu | K51: 46104 | L51: =TODAY() -> 46106 | M51: 36 | N51: =(K51-L51)/30 -> -0.066666667 | O51: =N51/M51 -> -0.0018518519 | R51: 20/3/2026
A52: Guardian | B52: B2B | C52: Tháng 8 | D52: 8809526841409 | E52: Phấn nước trang điểm GLAMRR Q (VEGAN SUPER GLOW CUSHION #02 NATURAL BEIGE, 15g) | F52: =IF(ISNUMBER(SEARCH("gilaa",E52)),"GILAA", IF(ISNUMBER(SEARCH("GLAMRR Q",E52)),"GLAMRR Q", IF(ISNUMBER(SEARCH("BAD PEACH",E52)),"BAD PEACH", IF(ISNUMBER(SEARCH("VEGICK",E52)),"VEGICK", IF(ISNUMBER(SEARCH("DE MEMORIA",E52)),"DE MEMORIA", IF(ISNUMBER(SEARCH("MUDE",E52)),"MUDE", IF(ISNUMBER(SEARCH("daoida",E52)),"DAOIDA",IF(ISNUMBER(SEARCH("MEDIFORCELL",E52)),"MEDIFORCELL",IF(ISNUMBER(SEARCH("PLU",E52)),"PLU",""))))))))) -> GLAMRR Q | G52: 1 | I52: =G52-H52 -> 1 | J52: bao bì bị cấn móp | K52: 46104 | L52: =TODAY() -> 46106 | M52: 36 | N52: =(K52-L52)/30 -> -0.066666667 | O52: =N52/M52 -> -0.0018518519 | R52: 20/3/2026
A53: Guardian | B53: B2B | C53: Tháng 8 | D53: 8809864752238 | E53: Phấn nước trang điểm GLAMRR Q (LONG WEAR DD CUSHION #01 LIGHT BEIGE, 13g) | F53: =IF(ISNUMBER(SEARCH("gilaa",E53)),"GILAA", IF(ISNUMBER(SEARCH("GLAMRR Q",E53)),"GLAMRR Q", IF(ISNUMBER(SEARCH("BAD PEACH",E53)),"BAD PEACH", IF(ISNUMBER(SEARCH("VEGICK",E53)),"VEGICK", IF(ISNUMBER(SEARCH("DE MEMORIA",E53)),"DE MEMORIA", IF(ISNUMBER(SEARCH("MUDE",E53)),"MUDE", IF(ISNUMBER(SEARCH("daoida",E53)),"DAOIDA",IF(ISNUMBER(SEARCH("MEDIFORCELL",E53)),"MEDIFORCELL",IF(ISNUMBER(SEARCH("PLU",E53)),"PLU",""))))))))) -> GLAMRR Q | G53: 1 | I53: =G53-H53 -> 1 | J53: sản phẩm nguyên vẹn | K53: 46116 | L53: =TODAY() -> 46106 | M53: 36 | N53: =(K53-L53)/30 -> 0.33333333 | O53: =N53/M53 -> 0.0092592593 | R53: 20/3/2026
A54: Guardian | B54: B2B | C54: Tháng 8 | D54: 8809864752238 | E54: Phấn nước trang điểm GLAMRR Q (LONG WEAR DD CUSHION #01 LIGHT BEIGE, 13g) | F54: =IF(ISNUMBER(SEARCH("gilaa",E54)),"GILAA", IF(ISNUMBER(SEARCH("GLAMRR Q",E54)),"GLAMRR Q", IF(ISNUMBER(SEARCH("BAD PEACH",E54)),"BAD PEACH", IF(ISNUMBER(SEARCH("VEGICK",E54)),"VEGICK", IF(ISNUMBER(SEARCH("DE MEMORIA",E54)),"DE MEMORIA", IF(ISNUMBER(SEARCH("MUDE",E54)),"MUDE", IF(ISNUMBER(SEARCH("daoida",E54)),"DAOIDA",IF(ISNUMBER(SEARCH("MEDIFORCELL",E54)),"MEDIFORCELL",IF(ISNUMBER(SEARCH("PLU",E54)),"PLU",""))))))))) -> GLAMRR Q | G54: 9 | I54: =G54-H54 -> 9 | J54: bao bì bị bạc màu | K54: 46116 | L54: =TODAY() -> 46106 | M54: 36 | N54: =(K54-L54)/30 -> 0.33333333 | O54: =N54/M54 -> 0.0092592593 | R54: 20/3/2026
... A87: Guardian | B87: B2B | C87: Tháng 8 | D87: 8809491946239 | E87: Son môi GLAMRR Q (LONG WEAR LIP CREAM #09 HEI HEI, 5g) | F87: =IF(ISNUMBER(SEARCH("gilaa",E87)),"GILAA", IF(ISNUMBER(SEARCH("GLAMRR Q",E87)),"GLAMRR Q", IF(ISNUMBER(SEARCH("BAD PEACH",E87)),"BAD PEACH", IF(ISNUMBER(SEARCH("VEGICK",E87)),"VEGICK", IF(ISNUMBER(SEARCH("DE MEMORIA",E87)),"DE MEMORIA", IF(ISNUMBER(SEARCH("MUDE",E87)),"MUDE", IF(ISNUMBER(SEARCH("daoida",E87)),"DAOIDA",IF(ISNUMBER(SEARCH("MEDIFORCELL",E87)),"MEDIFORCELL",IF(ISNUMBER(SEARCH("PLU",E87)),"PLU",""))))))))) -> GLAMRR Q | G87: 1 | I87: =G87-H87 -> 1 | J87: sản phẩm nguyên vẹn | K87: 46472 | L87: =TODAY() -> 46106 | M87: 36 | N87: =(K87-L87)/30 -> 12.2 | O87: =N87/M87 -> 0.33888889 | R87: 20/3/2026
A88: Guardian | B88: B2B | C88: Tháng 9 | D88: 8809203078210 | E88: Thực phẩm bổ sung GILAA (5K COLLAGEN BRIGHT BOOSTER WITH SAFFRON, 20g x 15), hộp 15 gói | F88: =IF(ISNUMBER(SEARCH("gilaa",E88)),"GILAA", IF(ISNUMBER(SEARCH("GLAMRR Q",E88)),"GLAMRR Q", IF(ISNUMBER(SEARCH("BAD PEACH",E88)),"BAD PEACH", IF(ISNUMBER(SEARCH("VEGICK",E88)),"VEGICK", IF(ISNUMBER(SEARCH("DE MEMORIA",E88)),"DE MEMORIA", IF(ISNUMBER(SEARCH("MUDE",E88)),"MUDE", IF(ISNUMBER(SEARCH("daoida",E88)),"DAOIDA",IF(ISNUMBER(SEARCH("MEDIFORCELL",E88)),"MEDIFORCELL",IF(ISNUMBER(SEARCH("PLU",E88)),"PLU",""))))))))) -> GILAA | G88: 2 | I88: =G88-H88 -> 2 | J88: sản phẩm nguyên vẹn | K88: 46268 | L88: =TODAY() -> 46106 | M88: 36 | N88: =(K88-L88)/30 -> 5.4 | O88: =N88/M88 -> 0.15 | Q88: B2B lên đơn trên CRM, KT check sl giúp nha | R88: 20/3/2026
A89: Guardian | B89: B2B | C89: Tháng 9 | D89: 8809491946154 | E89: Son môi GLAMRR Q (LONG WEAR LIP CREAM #01 GLAD DAY, 5g) | F89: =IF(ISNUMBER(SEARCH("gilaa",E89)),"GILAA", IF(ISNUMBER(SEARCH("GLAMRR Q",E89)),"GLAMRR Q", IF(ISNUMBER(SEARCH("BAD PEACH",E89)),"BAD PEACH", IF(ISNUMBER(SEARCH("VEGICK",E89)),"VEGICK", IF(ISNUMBER(SEARCH("DE MEMORIA",E89)),"DE MEMORIA", IF(ISNUMBER(SEARCH("MUDE",E89)),"MUDE", IF(ISNUMBER(SEARCH("daoida",E89)),"DAOIDA",IF(ISNUMBER(SEARCH("MEDIFORCELL",E89)),"MEDIFORCELL",IF(ISNUMBER(SEARCH("PLU",E89)),"PLU",""))))))))) -> GLAMRR Q | G89: 6 | I89: =G89-H89 -> 6 | J89: bao bì bạc màu | K89: 46052 | L89: =TODAY() -> 46106 | M89: 36 | N89: =(K89-L89)/30 -> -1.8 | O89: =N89/M89 -> -0.05 | R89: 20/3/2026
A90: Guardian | B90: B2B | C90: Tháng 9 | D90: 8809491946154 | E90: Son môi GLAMRR Q (LONG WEAR LIP CREAM #01 GLAD DAY, 5g) | F90: =IF(ISNUMBER(SEARCH("gilaa",E90)),"GILAA", IF(ISNUMBER(SEARCH("GLAMRR Q",E90)),"GLAMRR Q", IF(ISNUMBER(SEARCH("BAD PEACH",E90)),"BAD PEACH", IF(ISNUMBER(SEARCH("VEGICK",E90)),"VEGICK", IF(ISNUMBER(SEARCH("DE MEMORIA",E90)),"DE MEMORIA", IF(ISNUMBER(SEARCH("MUDE",E90)),"MUDE", IF(ISNUMBER(SEARCH("daoida",E90)),"DAOIDA",IF(ISNUMBER(SEARCH("MEDIFORCELL",E90)),"MEDIFORCELL",IF(ISNUMBER(SEARCH("PLU",E90)),"PLU",""))))))))) -> GLAMRR Q | G90: =29+7 -> 36 | I90: =G90-H90 -> 36 | J90: bao bì bạc màu | K90: 46222 | L90: =TODAY() -> 46106 | M90: 36 | N90: =(K90-L90)/30 -> 3.8666667 | O90: =N90/M90 -> 0.10740741 | R90: 20/3/2026
A91: Guardian | B91: B2B | C91: Tháng 9 | D91: 8809491946154 | E91: Son môi GLAMRR Q (LONG WEAR LIP CREAM #01 GLAD DAY, 5g) | F91: =IF(ISNUMBER(SEARCH("gilaa",E91)),"GILAA", IF(ISNUMBER(SEARCH("GLAMRR Q",E91)),"GLAMRR Q", IF(ISNUMBER(SEARCH("BAD PEACH",E91)),"BAD PEACH", IF(ISNUMBER(SEARCH("VEGICK",E91)),"VEGICK", IF(ISNUMBER(SEARCH("DE MEMORIA",E91)),"DE MEMORIA", IF(ISNUMBER(SEARCH("MUDE",E91)),"MUDE", IF(ISNUMBER(SEARCH("daoida",E91)),"DAOIDA",IF(ISNUMBER(SEARCH("MEDIFORCELL",E91)),"MEDIFORCELL",IF(ISNUMBER(SEARCH("PLU",E91)),"PLU",""))))))))) -> GLAMRR Q | G91: 5 | I91: =G91-H91 -> 5 | J91: bao bì bạc màu | K91: 46349 | L91: =TODAY() -> 46106 | M91: 36 | N91: =(K91-L91)/30 -> 8.1 | O91: =N91/M91 -> 0.225 | R91: 20/3/2026
A92: Guardian | B92: B2B | C92: Tháng 9 | D92: 8809491946154 | E92: Son môi GLAMRR Q (LONG WEAR LIP CREAM #01 GLAD DAY, 5g) | F92: =IF(ISNUMBER(SEARCH("gilaa",E92)),"GILAA", IF(ISNUMBER(SEARCH("GLAMRR Q",E92)),"GLAMRR Q", IF(ISNUMBER(SEARCH("BAD PEACH",E92)),"BAD PEACH", IF(ISNUMBER(SEARCH("VEGICK",E92)),"VEGICK", IF(ISNUMBER(SEARCH("DE MEMORIA",E92)),"DE MEMORIA", IF(ISNUMBER(SEARCH("MUDE",E92)),"MUDE", IF(ISNUMBER(SEARCH("daoida",E92)),"DAOIDA",IF(ISNUMBER(SEARCH("MEDIFORCELL",E92)),"MEDIFORCELL",IF(ISNUMBER(SEARCH("PLU",E92)),"PLU",""))))))))) -> GLAMRR Q | G92: 100 | H92: 1 | I92: =G92-H92 -> 99 | J92: bao bì bạc màu | K92: 46640 | L92: =TODAY() -> 46106 | M92: 36 | N92: =(K92-L92)/30 -> 17.8 | O92: =N92/M92 -> 0.49444444 | Q92: https://workflow.base.vn/job/3581351 | R92: 20/3/2026
A93: Guardian | B93: B2B | C93: Tháng 9 | D93: 8809491946161 | E93: Son môi GLAMRR Q (LONG WEAR LIP CREAM #02 LOVELY DAY, 5g) | F93: =IF(ISNUMBER(SEARCH("gilaa",E93)),"GILAA", IF(ISNUMBER(SEARCH("GLAMRR Q",E93)),"GLAMRR Q", IF(ISNUMBER(SEARCH("BAD PEACH",E93)),"BAD PEACH", IF(ISNUMBER(SEARCH("VEGICK",E93)),"VEGICK", IF(ISNUMBER(SEARCH("DE MEMORIA",E93)),"DE MEMORIA", IF(ISNUMBER(SEARCH("MUDE",E93)),"MUDE", IF(ISNUMBER(SEARCH("daoida",E93)),"DAOIDA",IF(ISNUMBER(SEARCH("MEDIFORCELL",E93)),"MEDIFORCELL",IF(ISNUMBER(SEARCH("PLU",E93)),"PLU",""))))))))) -> GLAMRR Q | G93: 11 | I93: =G93-H93 -> 11 | J93: bao bì bạc màu | K93: 46061 | L93: =TODAY() -> 46106 | M93: 36 | N93: =(K93-L93)/30 -> -1.5 | O93: =N93/M93 -> -0.041666667 | R93: 20/3/2026
A94: Guardian | B94: B2B | C94: Tháng 9 | D94: 8809491946161 | E94: Son môi GLAMRR Q (LONG WEAR LIP CREAM #02 LOVELY DAY, 5g) | F94: =IF(ISNUMBER(SEARCH("gilaa",E94)),"GILAA", IF(ISNUMBER(SEARCH("GLAMRR Q",E94)),"GLAMRR Q", IF(ISNUMBER(SEARCH("BAD PEACH",E94)),"BAD PEACH", IF(ISNUMBER(SEARCH("VEGICK",E94)),"VEGICK", IF(ISNUMBER(SEARCH("DE MEMORIA",E94)),"DE MEMORIA", IF(ISNUMBER(SEARCH("MUDE",E94)),"MUDE", IF(ISNUMBER(SEARCH("daoida",E94)),"DAOIDA",IF(ISNUMBER(SEARCH("MEDIFORCELL",E94)),"MEDIFORCELL",IF(ISNUMBER(SEARCH("PLU",E94)),"PLU",""))))))))) -> GLAMRR Q | G94: 8 | I94: =G94-H94 -> 8 | J94: bao bì bạc màu | K94: 46201 | L94: =TODAY() -> 46106 | M94: 36 | N94: =(K94-L94)/30 -> 3.1666667 | O94: =N94/M94 -> 0.087962963 | R94: 20/3/2026
A95: Guardian | B95: B2B | C95: Tháng 9 | D95: 8809491946178 | E95: Son môi GLAMRR Q (LONG WEAR LIP CREAM #03 SUNSHINE DAY, 5g) | F95: =IF(ISNUMBER(SEARCH("gilaa",E95)),"GILAA", IF(ISNUMBER(SEARCH("GLAMRR Q",E95)),"GLAMRR Q", IF(ISNUMBER(SEARCH("BAD PEACH",E95)),"BAD PEACH", IF(ISNUMBER(SEARCH("VEGICK",E95)),"VEGICK", IF(ISNUMBER(SEARCH("DE MEMORIA",E95)),"DE MEMORIA", IF(ISNUMBER(SEARCH("MUDE",E95)),"MUDE", IF(ISNUMBER(SEARCH("daoida",E95)),"DAOIDA",IF(ISNUMBER(SEARCH("MEDIFORCELL",E95)),"MEDIFORCELL",IF(ISNUMBER(SEARCH("PLU",E95)),"PLU",""))))))))) -> GLAMRR Q | G95: 7 | I95: =G95-H95 -> 7 | J95: bao bì bạc màu | K95: 46061 | L95: =TODAY() -> 46106 | M95: 36 | N95: =(K95-L95)/30 -> -1.5 | O95: =N95/M95 -> -0.041666667 | R95: 20/3/2026
A96: Guardian | B96: B2B | C96: Tháng 9 | D96: 8809491946185 | E96: Son môi GLAMRR Q (LONG WEAR LIP CREAM #04 FIRST DAY, 5g) | F96: =IF(ISNUMBER(SEARCH("gilaa",E96)),"GILAA", IF(ISNUMBER(SEARCH("GLAMRR Q",E96)),"GLAMRR Q", IF(ISNUMBER(SEARCH("BAD PEACH",E96)),"BAD PEACH", IF(ISNUMBER(SEARCH("VEGICK",E96)),"VEGICK", IF(ISNUMBER(SEARCH("DE MEMORIA",E96)),"DE MEMORIA", IF(ISNUMBER(SEARCH("MUDE",E96)),"MUDE", IF(ISNUMBER(SEARCH("daoida",E96)),"DAOIDA",IF(ISNUMBER(SEARCH("MEDIFORCELL",E96)),"MEDIFORCELL",IF(ISNUMBER(SEARCH("PLU",E96)),"PLU",""))))))))) -> GLAMRR Q | G96: 6 | I96: =G96-H96 -> 6 | J96: bao bì bạc màu | K96: 46061 | L96: =TODAY() -> 46106 | M96: 36 | N96: =(K96-L96)/30 -> -1.5 | O96: =N96/M96 -> -0.041666667 | R96: 20/3/2026
A97: Guardian | B97: B2B | C97: Tháng 9 | D97: 8809491946185 | E97: Son môi GLAMRR Q (LONG WEAR LIP CREAM #04 FIRST DAY, 5g) | F97: =IF(ISNUMBER(SEARCH("gilaa",E97)),"GILAA", IF(ISNUMBER(SEARCH("GLAMRR Q",E97)),"GLAMRR Q", IF(ISNUMBER(SEARCH("BAD PEACH",E97)),"BAD PEACH", IF(ISNUMBER(SEARCH("VEGICK",E97)),"VEGICK", IF(ISNUMBER(SEARCH("DE MEMORIA",E97)),"DE MEMORIA", IF(ISNUMBER(SEARCH("MUDE",E97)),"MUDE", IF(ISNUMBER(SEARCH("daoida",E97)),"DAOIDA",IF(ISNUMBER(SEARCH("MEDIFORCELL",E97)),"MEDIFORCELL",IF(ISNUMBER(SEARCH("PLU",E97)),"PLU",""))))))))) -> GLAMRR Q | G97: 16 | I97: =G97-H97 -> 16 | J97: bao bì bạc màu | K97: 46221 | L97: =TODAY() -> 46106 | M97: 36 | N97: =(K97-L97)/30 -> 3.8333333 | O97: =N97/M97 -> 0.10648148 | R97: 20/3/2026
A98: Guardian | B98: B2B | C98: Tháng 9 | D98: 8809491946185 | E98: Son môi GLAMRR Q (LONG WEAR LIP CREAM #04 FIRST DAY, 5g) | F98: =IF(ISNUMBER(SEARCH("gilaa",E98)),"GILAA", IF(ISNUMBER(SEARCH("GLAMRR Q",E98)),"GLAMRR Q", IF(ISNUMBER(SEARCH("BAD PEACH",E98)),"BAD PEACH", IF(ISNUMBER(SEARCH("VEGICK",E98)),"VEGICK", IF(ISNUMBER(SEARCH("DE MEMORIA",E98)),"DE MEMORIA", IF(ISNUMBER(SEARCH("MUDE",E98)),"MUDE", IF(ISNUMBER(SEARCH("daoida",E98)),"DAOIDA",IF(ISNUMBER(SEARCH("MEDIFORCELL",E98)),"MEDIFORCELL",IF(ISNUMBER(SEARCH("PLU",E98)),"PLU",""))))))))) -> GLAMRR Q | G98: 7 | I98: =G98-H98 -> 7 | J98: bao bì bạc màu | K98: 46349 | L98: =TODAY() -> 46106 | M98: 36 | N98: =(K98-L98)/30 -> 8.1 | O98: =N98/M98 -> 0.225 | R98: 20/3/2026
...

Sheet Report
A3: Nội dung | B3: Tổng cộng | C3: Tỷ lệ (%)
A4: PO - hàng cấn móp | B4: 4 | C4: 0.00068108292
A5: Boxme thu hồi | B5: 1395 | C5: 0.23752767
A6: B2B | B6: 4474 | C6: 0.76179125
A7: Grand Total | B7: 5873 | C7: 1
A11: Chi tiết | B11: Tổng cộng | C11: Tỷ lệ (%)
A12: 011/2025/PO/OQR-MUDE | B12: 1 | C12: 0.00017027073
A13: Mộc Beautiful | B13: 1 | C13: 0.00017027073
A14: 009/2025/PO/OQR-MUDE | B14: 1 | C14: 0.00017027073
A15: 012/2025/PO/OQR-MUDE | B15: 2 | C15: 0.00034054146
A16: B2B | B16: 5 | C16: 0.00085135365
A17: BM68698317418DM | B17: 13 | C17: 0.0022135195
A18: HASAKI | B18: 237 | C18: 0.040354163
A19: BM631962340681DM | B19: 1382 | C19: 0.23531415
A20: Guardian | B20: 4231 | C20: 0.72041546
A21: Grand Total | B21: 5873 | C21: 1

Sheet Dang_le
A1: STT | B1: NGÀY CẬP NHẬT | C1: BARCODE | D1: TÊN GỌI CHÍNH THỨC CỦA SẢN PHẨM | E1: ĐƠN VỊ TÍNH | F1: KHỐI LƯỢNG (GRAM) | G1: GIÁ BÁN LẺ THƯỜNG NIÊN (đã bao gồm VAT) (VNĐ) | H1: TÌNH TRẠNG | I1: ND TRƯỚC THAY ĐỔI | J1: MỤC ĐÍCH SỬ DỤNG (Bán/ Quà tặng/ Cả bán và tặng) Chỉ điền với sản phẩm minisize và vật phẩm | K1: GHI CHÚ
A2: 1 | B2: 44580 | C2: 8803348041672 | D2: Tinh chất dưỡng da AESTHENIA (PEPTIDE BIFIDA TONING VITAL AMPOULE, 35ml) | E2: Hộp | F2: 158 | G2: 390000 | H2: Tạo mới
A3: =ROW()-ROW($A$1) -> 2 | B3: 44580 | C3: 8803348041665 | D3: Tinh chất dưỡng da AESTHENIA (PEPTIDE HYALURONIC TENSION S.O.S AMPOULE, 35ml) | E3: Hộp | F3: 158 | G3: 390000 | H3: Ngưng kinh doanh
A4: 3 | B4: 44580 | C4: 8803348041689 | D4: Tinh chất dưỡng da AESTHENIA (PEPTIDE MARINE COLLAGEN CALMING AQUA AMPOULE, 35ml) | E4: Hộp | F4: 158 | G4: 390000 | H4: Tạo mới
A5: 4 | B5: 44580 | C5: 8809738603505 | D5: Nước hoa DE MEMORIA (SPELLO #01, 30ml) | E5: Hộp | F5: 119 | G5: 425000 | H5: Tạo mới | I5: Giá cũ: 390.000 | J5: Bán | K5: 05/02/2025 Update lại giá
A6: 5 | B6: 44580 | C6: 8809738603499 | D6: Nước hoa DE MEMORIA (VAL DE LOIRE #02, 30ml) | E6: Hộp | F6: 119 | G6: 425000 | H6: Tạo mới | I6: Giá cũ: 390.000 | J6: Bán | K6: 05/02/2025 Update lại giá
A7: 6 | B7: 44580 | C7: 8809738605509 | D7: Nước hoa DE MEMORIA (GRANADA #03, 30ml) | E7: Hộp | F7: 119 | G7: 390000 | H7: Tạo mới
A8: 7 | B8: 44580 | C8: 8809738603512 | D8: Nước hoa DE MEMORIA (DRESDEN #04, 30ml) | E8: Hộp | F8: 119 | G8: 425000 | H8: Tạo mới | I8: Giá cũ: 390.000 | J8: Bán | K8: 05/02/2025 Update lại giá
A9: 8 | B9: 44580 | C9: 8809738603482 | D9: Nước hoa DE MEMORIA (MONTPELLIER #05, 30ml) | E9: Hộp | F9: 119 | G9: 425000 | H9: Tạo mới | I9: Giá cũ: 390.000 | J9: Bán | K9: 05/02/2025 Update lại giá
A10: 9 | B10: 44580 | C10: 8809738605516 | D10: Nước hoa DE MEMORIA (GRASSE #06, 30ml) | E10: Hộp | F10: 119 | G10: 200000 | H10: Tạo mới | I10: Giá cũ: 390.000 | J10: Cả bán và tặng | K10: 10/01/2025 Update lại giá và mục đích sử dụng
A11: 10 | B11: 44580 | C11: 8809657119224 | D11: Phấn nước trang điểm chưa nén GILAA (LONG WEAR DD CUSHION #01 LIGHT BEIGE, 13g) | E11: Hộp | F11: 85 | G11: 345000 | H11: Tạo mới
A12: 11 | B12: 44580 | C12: 8809657119231 | D12: Phấn nước trang điểm chưa nén GILAA (LONG WEAR DD CUSHION #02 NATURAL BEIGE, 13g) | E12: Hộp | F12: 85 | G12: 345000 | H12: Tạo mới
A13: 12 | B13: 44580 | C13: 8809491944020 | D13: Son môi GILAA (LONG WEAR LIP CREAM #01 GLAD DAY, 5g) | E13: Hộp | F13: 30 | G13: 199000 | H13: Tạo mới
A14: 13 | B14: 44580 | C14: 8809491944037 | D14: Son môi GILAA (LONG WEAR LIP CREAM #02 LOVELY DAY, 5g) | E14: Hộp | F14: 30 | G14: 199000 | H14: Tạo mới
A15: 14 | B15: 44580 | C15: 8809491944044 | D15: Son môi GILAA (LONG WEAR LIP CREAM #03 SUNSHINE DAY, 5g) | E15: Hộp | F15: 30 | G15: 199000 | H15: Tạo mới
A16: 15 | B16: 44580 | C16: 8809491944051 | D16: Son môi GILAA (LONG WEAR LIP CREAM #04 FIRST DAY, 5g) | E16: Hộp | F16: 30 | G16: 199000 | H16: Tạo mới
A17: 16 | B17: 44580 | C17: 8809491944068 | D17: Son môi GILAA (LONG WEAR LIP CREAM #05 GLOOMY DAY, 5g) | E17: Hộp | F17: 30 | G17: 199000 | H17: Tạo mới
A18: 17 | B18: 44580 | C18: 8809491944075 | D18: Son môi GILAA (LONG WEAR LIP CREAM #06 RAINY DAY, 5g) | E18: Hộp | F18: 30 | G18: 199000 | H18: Tạo mới
A19: 18 | B19: 44580 | C19: 8809491944433 | D19: Son môi GILAA (LONG WEAR LIP CREAM #07 RED-LETTER DAY, 5g) | E19: Hộp | F19: 30 | G19: 199000 | H19: Tạo mới
A20: 19 | B20: 44580 | C20: 8809491944082 | D20: Son môi GILAA (LONG WEAR LIP CREAM #01 GLAD DAY, 1.7g) | E20: Hộp | F20: 17 | G20: 180000 | H20: Tạo mới | J20: Cả bán và tặng | K20: Kênh official để giá niêm yết treo bán
A21: 20 | B21: 44580 | C21: 8809491944099 | D21: Son môi GILAA (LONG WEAR LIP CREAM #02 LOVELY DAY, 1.7g) | E21: Hộp | F21: 17 | G21: 180000 | H21: Tạo mới | J21: Cả bán và tặng | K21: Kênh official để giá niêm yết treo bán
A22: 21 | B22: 44580 | C22: 8809491944112 | D22: Son môi GILAA (LONG WEAR LIP CREAM #04 FIRST DAY, 1.7g) | E22: Hộp | F22: 17 | G22: 180000 | H22: Tạo mới | J22: Cả bán và tặng | K22: Kênh official để giá niêm yết treo bán
A23: 22 | B23: 44580 | C23: 8809491945447 | D23: Son môi GILAA (LONG WEAR LIP CREAM #08 TAKE A SIP, 5g) | E23: Hộp | F23: 30 | G23: 229000 | H23: Tạo mới
A24: 23 | B24: 44580 | C24: 8809491945454 | D24: Son môi GILAA (LONG WEAR LIP CREAM #09 HEI HEI, 5g) | E24: Hộp | F24: 30 | G24: 229000 | H24: Tạo mới
A25: 24 | B25: 44580 | C25: 8809491945461 | D25: Son môi GILAA (LONG WEAR LIP CREAM #10 MAY BEAUTY, 5g) | E25: Hộp | F25: 30 | G25: 229000 | H25: Tạo mới
A26: 25 | B26: 44580 | C26: 8809491945478 | D26: Son môi GILAA (LONG WEAR LIP CREAM #11 SET SAIL, 5g) | E26: Hộp | F26: 30 | G26: 229000 | H26: Tạo mới
A27: 26 | B27: 44580 | C27: 8809491945485 | D27: Son môi GILAA (LONG WEAR LIP CREAM #12 LAVISH, 5g) | E27: Hộp | F27: 30 | G27: 229000 | H27: Tạo mới
A28: 27 | B28: 44580 | C28: 8809491945492 | D28: Son môi GILAA (LONG WEAR LIP CREAM #13 CURSE REVERSE, 5g) | E28: Hộp | F28: 30 | G28: 229000 | H28: Tạo mới
A29: 28 | B29: 44580 | C29: 8809491945447 | D29: Son môi GILAA (LONG WEAR LIP CREAM #08 TAKE A SIP, 5g), bản giới hạn | E29: Hộp | F29: 37 | G29: 229000 | H29: Tạo mới
A30: 29 | B30: 44580 | C30: 8809491945454 | D30: Son môi GILAA (LONG WEAR LIP CREAM #09 HEI HEI, 5g), bản giới hạn | E30: Hộp | F30: 37 | G30: 229000 | H30: Tạo mới
A31: 30 | B31: 44580 | C31: 8809491945461 | D31: Son môi GILAA (LONG WEAR LIP CREAM #10 MAY BEAUTY, 5g), bản giới hạn | E31: Hộp | F31: 37 | G31: 229000 | H31: Tạo mới
A32: 31 | B32: 44580 | C32: 8809491945478 | D32: Son môi GILAA (LONG WEAR LIP CREAM #11 SET SAIL, 5g), bản giới hạn | E32: Hộp | F32: 37 | G32: 229000 | H32: Tạo mới
A33: 32 | B33: 44580 | C33: 8809491945485 | D33: Son môi GILAA (LONG WEAR LIP CREAM #12 LAVISH, 5g), bản giới hạn | E33: Hộp | F33: 37 | G33: 229000 | H33: Tạo mới
A34: 33 | B34: 44580 | C34: 8809491945492 | D34: Son môi GILAA (LONG WEAR LIP CREAM #13 CURSE REVERSE, 5g), bản giới hạn | E34: Hộp | F34: 37 | G34: 229000 | H34: Tạo mới
... A43: 42 | B43: 44580 | C43: 8809738595824 | D43: Sữa rửa mặt GILAA (PLANT SERUM CLEANSER WITH BITTER MELON + BHA, 160g) | E43: Hộp | F43: 228 | G43: 286000 | H43: Tạo mới
A44: 43 | B44: 44580 | C44: 8809738596074 | D44: Sữa rửa mặt GILAA (PLANT SERUM CLEANSER WITH BITTER MELON + BHA, 23g) | E44: Hộp | F44: 40 | G44: 125000 | H44: Tạo mới | J44: Cả bán và tặng | K44: Kênh official để giá niêm yết treo bán
A45: 44 | B45: 44580 | C45: 8809738595817 | D45: Sữa rửa mặt GILAA (PLANT SERUM CLEANSER WITH SAFFRON EXTRACT, 160g) | E45: Hộp | F45: 228 | G45: 286000 | H45: Tạo mới
A46: 45 | B46: 44580 | C46: 8809738596067 | D46: Sữa rửa mặt GILAA (PLANT SERUM CLEANSER WITH SAFFRON EXTRACT, 23g) | E46: Hộp | F46: 40 | G46: 125000 | H46: Tạo mới | J46: Cả bán và tặng | K46: Kênh official để giá niêm yết treo bán
A47: 46 | B47: 44580 | C47: 8809133684932-2 | D47: Thực phẩm bổ sung GILAA (PREMIUM SAFFRON COLLAGEN, 2g x 01), 01 gói | E47: Gói | F47: 44683 | G47: 8250 | H47: Tạo mới | J47: Quà tặng
A48: 47 | B48: 44580 | C48: 8936233680332 | D48: Thực phẩm bổ sung GILAA (PREMIUM SAFFRON COLLAGEN, 2g x 10), bịch 10 gói | E48: Bịch | F48: 26 | G48: 82500 | H48: Tạo mới | I48: Mã cũ: 8809133684932-1 Mục đích cũ: Quà tặng | J48: Cả bán và tặng | K48: 06/04/2025 cập nhật lại mã barcode 22/07/2025 cập nhật lại mục đích sủ dụng
...
